Workbook

Sheet Draft Board
A1: 2026 TD/FG-Only Draft Board — ranked by Adjusted VOR
A2: Rank | B2: Pos | C2: Player | D2: Tm | E2: P | F2: PassTD | G2: RushTD | H2: RecTD | I2: FG | J2: PAT | K2: DefTD | L2: Saf | M2: Points | N2: VOR | O2: Adj VOR | P2: Conf | Q2: Notes
A3: 1 | B3: QB1 | C3: Josh Allen | D3: BUF | E3: QB | F3: 27 | G3: 12 | M3: =F3*Settings!$B$4+G3*Settings!$B$5+H3*Settings!$B$6+I3*Settings!$B$7+J3*Settings!$B$8+K3*Settings!$B$9+L3*Settings!$B$10 | N3: =M3-INDEX(Settings!$G$4:$G$9,MATCH($E3,Settings!$F$4:$F$9,0)) | O3: =N3*INDEX(Settings!$H$4:$H$9,MATCH($E3,Settings!$F$4:$F$9,0)) | P3: HIGH | Q3: TIER OF ONE. 12 rush TDs alone outscore 20 of 40 QBs in total
A4: 2 | B4: RB1 | C4: Jahmyr Gibbs | D4: DET | E4: RB | G4: 13.4 | H4: 3.8 | M4: =F4*Settings!$B$4+G4*Settings!$B$5+H4*Settings!$B$6+I4*Settings!$B$7+J4*Settings!$B$8+K4*Settings!$B$9+L4*Settings!$B$10 | N4: =M4-INDEX(Settings!$G$4:$G$9,MATCH($E4,Settings!$F$4:$F$9,0)) | O4: =N4*INDEX(Settings!$H$4:$H$9,MATCH($E4,Settings!$F$4:$F$9,0)) | P4: HIGH | Q4: Overall RB1
A5: 3 | B5: RB2 | C5: Jonathan Taylor | D5: IND | E5: RB | G5: 12.2 | H5: 1.3 | M5: =F5*Settings!$B$4+G5*Settings!$B$5+H5*Settings!$B$6+I5*Settings!$B$7+J5*Settings!$B$8+K5*Settings!$B$9+L5*Settings!$B$10 | N5: =M5-INDEX(Settings!$G$4:$G$9,MATCH($E5,Settings!$F$4:$F$9,0)) | O5: =N5*INDEX(Settings!$H$4:$H$9,MATCH($E5,Settings!$F$4:$F$9,0)) | P5: HIGH | Q5: True goal-line back
A6: 4 | B6: RB3 | C6: Christian McCaffrey | D6: SF | E6: RB | G6: 9 | H6: 4.4 | M6: =F6*Settings!$B$4+G6*Settings!$B$5+H6*Settings!$B$6+I6*Settings!$B$7+J6*Settings!$B$8+K6*Settings!$B$9+L6*Settings!$B$10 | N6: =M6-INDEX(Settings!$G$4:$G$9,MATCH($E6,Settings!$F$4:$F$9,0)) | O6: =N6*INDEX(Settings!$H$4:$H$9,MATCH($E6,Settings!$F$4:$F$9,0)) | P6: HIGH | Q6: Goal-line yes
A7: 5 | B7: RB4 | C7: Derrick Henry | D7: BAL | E7: RB | G7: 12.8 | H7: 0.6 | M7: =F7*Settings!$B$4+G7*Settings!$B$5+H7*Settings!$B$6+I7*Settings!$B$7+J7*Settings!$B$8+K7*Settings!$B$9+L7*Settings!$B$10 | N7: =M7-INDEX(Settings!$G$4:$G$9,MATCH($E7,Settings!$F$4:$F$9,0)) | O7: =N7*INDEX(Settings!$H$4:$H$9,MATCH($E7,Settings!$F$4:$F$9,0)) | P7: HIGH | Q7: Vegas HIGHER than consensus here
A8: 6 | B8: QB2 | C8: Jalen Hurts | D8: PHI | E8: QB | F8: 24 | G8: 8.5 | M8: =F8*Settings!$B$4+G8*Settings!$B$5+H8*Settings!$B$6+I8*Settings!$B$7+J8*Settings!$B$8+K8*Settings!$B$9+L8*Settings!$B$10 | N8: =M8-INDEX(Settings!$G$4:$G$9,MATCH($E8,Settings!$F$4:$F$9,0)) | O8: =N8*INDEX(Settings!$H$4:$H$9,MATCH($E8,Settings!$F$4:$F$9,0)) | P8: HIGH | Q8: Tush push survived 2026 rules vote; goal-line sneak intact
A9: 7 | B9: RB5 | C9: James Cook III | D9: BUF | E9: RB | G9: 10.8 | H9: 1.8 | M9: =F9*Settings!$B$4+G9*Settings!$B$5+H9*Settings!$B$6+I9*Settings!$B$7+J9*Settings!$B$8+K9*Settings!$B$9+L9*Settings!$B$10 | N9: =M9-INDEX(Settings!$G$4:$G$9,MATCH($E9,Settings!$F$4:$F$9,0)) | O9: =N9*INDEX(Settings!$H$4:$H$9,MATCH($E9,Settings!$F$4:$F$9,0)) | P9: HIGH | Q9: Allen vulture tax already priced into line
A10: 8 | B10: RB6 | C10: Josh Jacobs | D10: GB | E10: RB | G10: 11.3 | H10: 1.3 | M10: =F10*Settings!$B$4+G10*Settings!$B$5+H10*Settings!$B$6+I10*Settings!$B$7+J10*Settings!$B$8+K10*Settings!$B$9+L10*Settings!$B$10 | N10: =M10-INDEX(Settings!$G$4:$G$9,MATCH($E10,Settings!$F$4:$F$9,0)) | O10: =N10*INDEX(Settings!$H$4:$H$9,MATCH($E10,Settings!$F$4:$F$9,0)) | P10: HIGH | Q10: Goal-line yes
A11: 9 | B11: WR1 | C11: Ja'Marr Chase | D11: CIN | E11: WR | G11: 0.1 | H11: 10.9 | M11: =F11*Settings!$B$4+G11*Settings!$B$5+H11*Settings!$B$6+I11*Settings!$B$7+J11*Settings!$B$8+K11*Settings!$B$9+L11*Settings!$B$10 | N11: =M11-INDEX(Settings!$G$4:$G$9,MATCH($E11,Settings!$F$4:$F$9,0)) | O11: =N11*INDEX(Settings!$H$4:$H$9,MATCH($E11,Settings!$F$4:$F$9,0)) | P11: HIGH
A12: 10 | B12: RB7 | C12: Bijan Robinson | D12: ATL | E12: RB | G12: 8.7 | H12: 3.3 | M12: =F12*Settings!$B$4+G12*Settings!$B$5+H12*Settings!$B$6+I12*Settings!$B$7+J12*Settings!$B$8+K12*Settings!$B$9+L12*Settings!$B$10 | N12: =M12-INDEX(Settings!$G$4:$G$9,MATCH($E12,Settings!$F$4:$F$9,0)) | O12: =N12*INDEX(Settings!$H$4:$H$9,MATCH($E12,Settings!$F$4:$F$9,0)) | P12: HIGH | Q12: CAUTION only 48 pct of inside-5 carries in 2025
A13: 11 | B13: RB8 | C13: Kyren Williams | D13: LAR | E13: RB | G13: 10.1 | H13: 1.8 | M13: =F13*Settings!$B$4+G13*Settings!$B$5+H13*Settings!$B$6+I13*Settings!$B$7+J13*Settings!$B$8+K13*Settings!$B$9+L13*Settings!$B$10 | N13: =M13-INDEX(Settings!$G$4:$G$9,MATCH($E13,Settings!$F$4:$F$9,0)) | O13: =N13*INDEX(Settings!$H$4:$H$9,MATCH($E13,Settings!$F$4:$F$9,0)) | P13: HIGH | Q13: Alternates drives with Corum
A14: 12 | B14: RB9 | C14: Javonte Williams | D14: DAL | E14: RB | G14: 10.6 | H14: 1.2 | M14: =F14*Settings!$B$4+G14*Settings!$B$5+H14*Settings!$B$6+I14*Settings!$B$7+J14*Settings!$B$8+K14*Settings!$B$9+L14*Settings!$B$10 | N14: =M14-INDEX(Settings!$G$4:$G$9,MATCH($E14,Settings!$F$4:$F$9,0)) | O14: =N14*INDEX(Settings!$H$4:$H$9,MATCH($E14,Settings!$F$4:$F$9,0)) | P14: HIGH | Q14: Goal-line yes
A15: 13 | B15: WR2 | C15: Davante Adams | D15: LAR | E15: WR | H15: 10.3 | M15: =F15*Settings!$B$4+G15*Settings!$B$5+H15*Settings!$B$6+I15*Settings!$B$7+J15*Settings!$B$8+K15*Settings!$B$9+L15*Settings!$B$10 | N15: =M15-INDEX(Settings!$G$4:$G$9,MATCH($E15,Settings!$F$4:$F$9,0)) | O15: =N15*INDEX(Settings!$H$4:$H$9,MATCH($E15,Settings!$F$4:$F$9,0)) | P15: HIGH
A16: 14 | B16: WR3 | C16: Amon-Ra St. Brown | D16: DET | E16: WR | G16: 0.1 | H16: 10.2 | M16: =F16*Settings!$B$4+G16*Settings!$B$5+H16*Settings!$B$6+I16*Settings!$B$7+J16*Settings!$B$8+K16*Settings!$B$9+L16*Settings!$B$10 | N16: =M16-INDEX(Settings!$G$4:$G$9,MATCH($E16,Settings!$F$4:$F$9,0)) | O16: =N16*INDEX(Settings!$H$4:$H$9,MATCH($E16,Settings!$F$4:$F$9,0)) | P16: HIGH
A17: 15 | B17: WR4 | C17: Puka Nacua | D17: LAR | E17: WR | G17: 0.6 | H17: 9.3 | M17: =F17*Settings!$B$4+G17*Settings!$B$5+H17*Settings!$B$6+I17*Settings!$B$7+J17*Settings!$B$8+K17*Settings!$B$9+L17*Settings!$B$10 | N17: =M17-INDEX(Settings!$G$4:$G$9,MATCH($E17,Settings!$F$4:$F$9,0)) | O17: =N17*INDEX(Settings!$H$4:$H$9,MATCH($E17,Settings!$F$4:$F$9,0)) | P17: HIGH
A18: 16 | B18: RB10 | C18: Omarion Hampton | D18: LAC | E18: RB | G18: 9.2 | H18: 1.9 | M18: =F18*Settings!$B$4+G18*Settings!$B$5+H18*Settings!$B$6+I18*Settings!$B$7+J18*Settings!$B$8+K18*Settings!$B$9+L18*Settings!$B$10 | N18: =M18-INDEX(Settings!$G$4:$G$9,MATCH($E18,Settings!$F$4:$F$9,0)) | O18: =N18*INDEX(Settings!$H$4:$H$9,MATCH($E18,Settings!$F$4:$F$9,0)) | P18: HIGH | Q18: Goal-line yes
A19: 17 | B19: K1 | C19: Jason Myers | D19: SEA | E19: K | I19: 39 | J19: 50 | M19: =F19*Settings!$B$4+G19*Settings!$B$5+H19*Settings!$B$6+I19*Settings!$B$7+J19*Settings!$B$8+K19*Settings!$B$9+L19*Settings!$B$10 | N19: =M19-INDEX(Settings!$G$4:$G$9,MATCH($E19,Settings!$F$4:$F$9,0)) | O19: =N19*INDEX(Settings!$H$4:$H$9,MATCH($E19,Settings!$F$4:$F$9,0)) | P19: HIGH | Q19: Led NFL 43 FGM 2025 on 48 FGA
A20: 18 | B20: RB11 | C20: Chase Brown | D20: CIN | E20: RB | G20: 7.4 | H20: 3.6 | M20: =F20*Settings!$B$4+G20*Settings!$B$5+H20*Settings!$B$6+I20*Settings!$B$7+J20*Settings!$B$8+K20*Settings!$B$9+L20*Settings!$B$10 | N20: =M20-INDEX(Settings!$G$4:$G$9,MATCH($E20,Settings!$F$4:$F$9,0)) | O20: =N20*INDEX(Settings!$H$4:$H$9,MATCH($E20,Settings!$F$4:$F$9,0)) | P20: HIGH | Q20: Vegas LOWER than consensus
A21: 19 | B21: RB12 | C21: Saquon Barkley | D21: PHI | E21: RB | G21: 8.6 | H21: 2.1 | M21: =F21*Settings!$B$4+G21*Settings!$B$5+H21*Settings!$B$6+I21*Settings!$B$7+J21*Settings!$B$8+K21*Settings!$B$9+L21*Settings!$B$10 | N21: =M21-INDEX(Settings!$G$4:$G$9,MATCH($E21,Settings!$F$4:$F$9,0)) | O21: =N21*INDEX(Settings!$H$4:$H$9,MATCH($E21,Settings!$F$4:$F$9,0)) | P21: HIGH | Q21: TRAP: Hurts vultures 8.5 rush TDs; not priced in
A22: 20 | B22: RB13 | C22: Kenneth Walker III | D22: KC | E22: RB | G22: 8.9 | H22: 1.6 | M22: =F22*Settings!$B$4+G22*Settings!$B$5+H22*Settings!$B$6+I22*Settings!$B$7+J22*Settings!$B$8+K22*Settings!$B$9+L22*Settings!$B$10 | N22: =M22-INDEX(Settings!$G$4:$G$9,MATCH($E22,Settings!$F$4:$F$9,0)) | O22: =N22*INDEX(Settings!$H$4:$H$9,MATCH($E22,Settings!$F$4:$F$9,0)) | P22: HIGH | Q22: New to KC; no established GL hierarchy
A23: 21 | B23: TE1 | C23: Brock Bowers | D23: LV | E23: TE | G23: 0.1 | H23: 6.8 | M23: =F23*Settings!$B$4+G23*Settings!$B$5+H23*Settings!$B$6+I23*Settings!$B$7+J23*Settings!$B$8+K23*Settings!$B$9+L23*Settings!$B$10 | N23: =M23-INDEX(Settings!$G$4:$G$9,MATCH($E23,Settings!$F$4:$F$9,0)) | O23: =N23*INDEX(Settings!$H$4:$H$9,MATCH($E23,Settings!$F$4:$F$9,0)) | P23: HIGH
A24: 22 | B24: TE2 | C24: Mark Andrews | D24: BAL | E24: TE | G24: 0.3 | H24: 6.5 | M24: =F24*Settings!$B$4+G24*Settings!$B$5+H24*Settings!$B$6+I24*Settings!$B$7+J24*Settings!$B$8+K24*Settings!$B$9+L24*Settings!$B$10 | N24: =M24-INDEX(Settings!$G$4:$G$9,MATCH($E24,Settings!$F$4:$F$9,0)) | O24: =N24*INDEX(Settings!$H$4:$H$9,MATCH($E24,Settings!$F$4:$F$9,0)) | P24: HIGH
A25: 23 | B25: K2 | C25: Ka'imi Fairbairn | D25: HOU | E25: K | I25: 39 | J25: 39 | M25: =F25*Settings!$B$4+G25*Settings!$B$5+H25*Settings!$B$6+I25*Settings!$B$7+J25*Settings!$B$8+K25*Settings!$B$9+L25*Settings!$B$10 | N25: =M25-INDEX(Settings!$G$4:$G$9,MATCH($E25,Settings!$F$4:$F$9,0)) | O25: =N25*INDEX(Settings!$H$4:$H$9,MATCH($E25,Settings!$F$4:$F$9,0)) | P25: HIGH | Q25: Best FG-lean in league; HOU led NFL 52 FGA
A26: 24 | B26: QB3 | C26: Joe Burrow | D26: CIN | E26: QB | F26: 33 | G26: 1.5 | M26: =F26*Settings!$B$4+G26*Settings!$B$5+H26*Settings!$B$6+I26*Settings!$B$7+J26*Settings!$B$8+K26*Settings!$B$9+L26*Settings!$B$10 | N26: =M26-INDEX(Settings!$G$4:$G$9,MATCH($E26,Settings!$F$4:$F$9,0)) | O26: =N26*INDEX(Settings!$H$4:$H$9,MATCH($E26,Settings!$F$4:$F$9,0)) | P26: HIGH | Q26: Volume passer; CIN 26.0 implied pts
A27: 25 | B27: QB4 | C27: Drake Maye | D27: NE | E27: QB | F27: 28 | G27: 4 | M27: =F27*Settings!$B$4+G27*Settings!$B$5+H27*Settings!$B$6+I27*Settings!$B$7+J27*Settings!$B$8+K27*Settings!$B$9+L27*Settings!$B$10 | N27: =M27-INDEX(Settings!$G$4:$G$9,MATCH($E27,Settings!$F$4:$F$9,0)) | O27: =N27*INDEX(Settings!$H$4:$H$9,MATCH($E27,Settings!$F$4:$F$9,0)) | P27: HIGH | Q27: NE 10.5 win total
A28: 26 | B28: WR5 | C28: CeeDee Lamb | D28: DAL | E28: WR | G28: 0.1 | H28: 8.3 | M28: =F28*Settings!$B$4+G28*Settings!$B$5+H28*Settings!$B$6+I28*Settings!$B$7+J28*Settings!$B$8+K28*Settings!$B$9+L28*Settings!$B$10 | N28: =M28-INDEX(Settings!$G$4:$G$9,MATCH($E28,Settings!$F$4:$F$9,0)) | O28: =N28*INDEX(Settings!$H$4:$H$9,MATCH($E28,Settings!$F$4:$F$9,0)) | P28: HIGH
A29: 27 | B29: K3 | C29: Brandon Aubrey | D29: DAL | E29: K | I29: 35 | J29: 49 | M29: =F29*Settings!$B$4+G29*Settings!$B$5+H29*Settings!$B$6+I29*Settings!$B$7+J29*Settings!$B$8+K29*Settings!$B$9+L29*Settings!$B$10 | N29: =M29-INDEX(Settings!$G$4:$G$9,MATCH($E29,Settings!$F$4:$F$9,0)) | O29: =N29*INDEX(Settings!$H$4:$H$9,MATCH($E29,Settings!$F$4:$F$9,0)) | P29: HIGH
A30: 28 | B30: WR6 | C30: Jaxon Smith-Njigba | D30: SEA | E30: WR | G30: 0.1 | H30: 8.2 | M30: =F30*Settings!$B$4+G30*Settings!$B$5+H30*Settings!$B$6+I30*Settings!$B$7+J30*Settings!$B$8+K30*Settings!$B$9+L30*Settings!$B$10 | N30: =M30-INDEX(Settings!$G$4:$G$9,MATCH($E30,Settings!$F$4:$F$9,0)) | O30: =N30*INDEX(Settings!$H$4:$H$9,MATCH($E30,Settings!$F$4:$F$9,0)) | P30: HIGH
A31: 29 | B31: K4 | C31: Blake Grupe | D31: IND | E31: K | I31: 34 | J31: 51 | M31: =F31*Settings!$B$4+G31*Settings!$B$5+H31*Settings!$B$6+I31*Settings!$B$7+J31*Settings!$B$8+K31*Settings!$B$9+L31*Settings!$B$10 | N31: =M31-INDEX(Settings!$G$4:$G$9,MATCH($E31,Settings!$F$4:$F$9,0)) | O31: =N31*INDEX(Settings!$H$4:$H$9,MATCH($E31,Settings!$F$4:$F$9,0)) | P31: MEDIUM | Q31: Shrader listed as backup
A32: 30 | B32: WR7 | C32: Rashee Rice | D32: KC | E32: WR | G32: 0.3 | H32: 7.9 | M32: =F32*Settings!$B$4+G32*Settings!$B$5+H32*Settings!$B$6+I32*Settings!$B$7+J32*Settings!$B$8+K32*Settings!$B$9+L32*Settings!$B$10 | N32: =M32-INDEX(Settings!$G$4:$G$9,MATCH($E32,Settings!$F$4:$F$9,0)) | O32: =N32*INDEX(Settings!$H$4:$H$9,MATCH($E32,Settings!$F$4:$F$9,0)) | P32: HIGH
A33: 31 | B33: WR8 | C33: Tee Higgins | D33: CIN | E33: WR | H33: 8.2 | M33: =F33*Settings!$B$4+G33*Settings!$B$5+H33*Settings!$B$6+I33*Settings!$B$7+J33*Settings!$B$8+K33*Settings!$B$9+L33*Settings!$B$10 | N33: =M33-INDEX(Settings!$G$4:$G$9,MATCH($E33,Settings!$F$4:$F$9,0)) | O33: =N33*INDEX(Settings!$H$4:$H$9,MATCH($E33,Settings!$F$4:$F$9,0)) | P33: HIGH
A34: 32 | B34: TE3 | C34: Trey McBride | D34: ARI | E34: TE | H34: 6.2 | M34: =F34*Settings!$B$4+G34*Settings!$B$5+H34*Settings!$B$6+I34*Settings!$B$7+J34*Settings!$B$8+K34*Settings!$B$9+L34*Settings!$B$10 | N34: =M34-INDEX(Settings!$G$4:$G$9,MATCH($E34,Settings!$F$4:$F$9,0)) | O34: =N34*INDEX(Settings!$H$4:$H$9,MATCH($E34,Settings!$F$4:$F$9,0)) | P34: HIGH
A35: 33 | B35: QB5 | C35: Trevor Lawrence | D35: JAX | E35: QB | F35: 26 | G35: 4.5 | M35: =F35*Settings!$B$4+G35*Settings!$B$5+H35*Settings!$B$6+I35*Settings!$B$7+J35*Settings!$B$8+K35*Settings!$B$9+L35*Settings!$B$10 | N35: =M35-INDEX(Settings!$G$4:$G$9,MATCH($E35,Settings!$F$4:$F$9,0)) | O35: =N35*INDEX(Settings!$H$4:$H$9,MATCH($E35,Settings!$F$4:$F$9,0)) | P35: HIGH
A36: 34 | B36: QB6 | C36: Matthew Stafford | D36: LAR | E36: QB | F36: 34 | G36: 0.5 | M36: =F36*Settings!$B$4+G36*Settings!$B$5+H36*Settings!$B$6+I36*Settings!$B$7+J36*Settings!$B$8+K36*Settings!$B$9+L36*Settings!$B$10 | N36: =M36-INDEX(Settings!$G$4:$G$9,MATCH($E36,Settings!$F$4:$F$9,0)) | O36: =N36*INDEX(Settings!$H$4:$H$9,MATCH($E36,Settings!$F$4:$F$9,0)) | P36: HIGH | Q36: LAR highest implied pts 26.6 but zero rush value
A37: 35 | B37: TE4 | C37: Colston Loveland | D37: CHI | E37: TE | H37: 6 | M37: =F37*Settings!$B$4+G37*Settings!$B$5+H37*Settings!$B$6+I37*Settings!$B$7+J37*Settings!$B$8+K37*Settings!$B$9+L37*Settings!$B$10 | N37: =M37-INDEX(Settings!$G$4:$G$9,MATCH($E37,Settings!$F$4:$F$9,0)) | O37: =N37*INDEX(Settings!$H$4:$H$9,MATCH($E37,Settings!$F$4:$F$9,0)) | P37: HIGH
A38: 36 | B38: WR9 | C38: Rome Odunze | D38: CHI | E38: WR | H38: 7.7 | M38: =F38*Settings!$B$4+G38*Settings!$B$5+H38*Settings!$B$6+I38*Settings!$B$7+J38*Settings!$B$8+K38*Settings!$B$9+L38*Settings!$B$10 | N38: =M38-INDEX(Settings!$G$4:$G$9,MATCH($E38,Settings!$F$4:$F$9,0)) | O38: =N38*INDEX(Settings!$H$4:$H$9,MATCH($E38,Settings!$F$4:$F$9,0)) | P38: HIGH
A39: 37 | B39: QB7 | C39: Dak Prescott | D39: DAL | E39: QB | F39: 30.5 | G39: 2 | M39: =F39*Settings!$B$4+G39*Settings!$B$5+H39*Settings!$B$6+I39*Settings!$B$7+J39*Settings!$B$8+K39*Settings!$B$9+L39*Settings!$B$10 | N39: =M39-INDEX(Settings!$G$4:$G$9,MATCH($E39,Settings!$F$4:$F$9,0)) | O39: =N39*INDEX(Settings!$H$4:$H$9,MATCH($E39,Settings!$F$4:$F$9,0)) | P39: HIGH
A40: 38 | B40: TE5 | C40: Dallas Goedert | D40: PHI | E40: TE | H40: 5.8 | M40: =F40*Settings!$B$4+G40*Settings!$B$5+H40*Settings!$B$6+I40*Settings!$B$7+J40*Settings!$B$8+K40*Settings!$B$9+L40*Settings!$B$10 | N40: =M40-INDEX(Settings!$G$4:$G$9,MATCH($E40,Settings!$F$4:$F$9,0)) | O40: =N40*INDEX(Settings!$H$4:$H$9,MATCH($E40,Settings!$F$4:$F$9,0)) | P40: HIGH
...

Sheet QB
A1: QB — ranked by projected points
A2: Rank | B2: Pos | C2: Player | D2: Tm | E2: P | F2: PassTD | G2: RushTD | H2: RecTD | I2: FG | J2: PAT | K2: DefTD | L2: Saf | M2: Points | N2: VOR | O2: Adj VOR | P2: Conf | Q2: Notes
A3: 1 | B3: QB1 | C3: Josh Allen | D3: BUF | E3: QB | F3: 27 | G3: 12 | M3: =F3*Settings!$B$4+G3*Settings!$B$5+H3*Settings!$B$6+I3*Settings!$B$7+J3*Settings!$B$8+K3*Settings!$B$9+L3*Settings!$B$10 | N3: =M3-INDEX(Settings!$G$4:$G$9,MATCH($E3,Settings!$F$4:$F$9,0)) | O3: =N3*INDEX(Settings!$H$4:$H$9,MATCH($E3,Settings!$F$4:$F$9,0)) | P3: HIGH | Q3: TIER OF ONE. 12 rush TDs alone outscore 20 of 40 QBs in total
A4: 6 | B4: QB2 | C4: Jalen Hurts | D4: PHI | E4: QB | F4: 24 | G4: 8.5 | M4: =F4*Settings!$B$4+G4*Settings!$B$5+H4*Settings!$B$6+I4*Settings!$B$7+J4*Settings!$B$8+K4*Settings!$B$9+L4*Settings!$B$10 | N4: =M4-INDEX(Settings!$G$4:$G$9,MATCH($E4,Settings!$F$4:$F$9,0)) | O4: =N4*INDEX(Settings!$H$4:$H$9,MATCH($E4,Settings!$F$4:$F$9,0)) | P4: HIGH | Q4: Tush push survived 2026 rules vote; goal-line sneak intact
A5: 24 | B5: QB3 | C5: Joe Burrow | D5: CIN | E5: QB | F5: 33 | G5: 1.5 | M5: =F5*Settings!$B$4+G5*Settings!$B$5+H5*Settings!$B$6+I5*Settings!$B$7+J5*Settings!$B$8+K5*Settings!$B$9+L5*Settings!$B$10 | N5: =M5-INDEX(Settings!$G$4:$G$9,MATCH($E5,Settings!$F$4:$F$9,0)) | O5: =N5*INDEX(Settings!$H$4:$H$9,MATCH($E5,Settings!$F$4:$F$9,0)) | P5: HIGH | Q5: Volume passer; CIN 26.0 implied pts
A6: 25 | B6: QB4 | C6: Drake Maye | D6: NE | E6: QB | F6: 28 | G6: 4 | M6: =F6*Settings!$B$4+G6*Settings!$B$5+H6*Settings!$B$6+I6*Settings!$B$7+J6*Settings!$B$8+K6*Settings!$B$9+L6*Settings!$B$10 | N6: =M6-INDEX(Settings!$G$4:$G$9,MATCH($E6,Settings!$F$4:$F$9,0)) | O6: =N6*INDEX(Settings!$H$4:$H$9,MATCH($E6,Settings!$F$4:$F$9,0)) | P6: HIGH | Q6: NE 10.5 win total
A7: 33 | B7: QB5 | C7: Trevor Lawrence | D7: JAX | E7: QB | F7: 26 | G7: 4.5 | M7: =F7*Settings!$B$4+G7*Settings!$B$5+H7*Settings!$B$6+I7*Settings!$B$7+J7*Settings!$B$8+K7*Settings!$B$9+L7*Settings!$B$10 | N7: =M7-INDEX(Settings!$G$4:$G$9,MATCH($E7,Settings!$F$4:$F$9,0)) | O7: =N7*INDEX(Settings!$H$4:$H$9,MATCH($E7,Settings!$F$4:$F$9,0)) | P7: HIGH
A8: 34 | B8: QB6 | C8: Matthew Stafford | D8: LAR | E8: QB | F8: 34 | G8: 0.5 | M8: =F8*Settings!$B$4+G8*Settings!$B$5+H8*Settings!$B$6+I8*Settings!$B$7+J8*Settings!$B$8+K8*Settings!$B$9+L8*Settings!$B$10 | N8: =M8-INDEX(Settings!$G$4:$G$9,MATCH($E8,Settings!$F$4:$F$9,0)) | O8: =N8*INDEX(Settings!$H$4:$H$9,MATCH($E8,Settings!$F$4:$F$9,0)) | P8: HIGH | Q8: LAR highest implied pts 26.6 but zero rush value
A9: 37 | B9: QB7 | C9: Dak Prescott | D9: DAL | E9: QB | F9: 30.5 | G9: 2 | M9: =F9*Settings!$B$4+G9*Settings!$B$5+H9*Settings!$B$6+I9*Settings!$B$7+J9*Settings!$B$8+K9*Settings!$B$9+L9*Settings!$B$10 | N9: =M9-INDEX(Settings!$G$4:$G$9,MATCH($E9,Settings!$F$4:$F$9,0)) | O9: =N9*INDEX(Settings!$H$4:$H$9,MATCH($E9,Settings!$F$4:$F$9,0)) | P9: HIGH
A10: 44 | B10: QB8 | C10: Jaxson Dart | D10: NYG | E10: QB | F10: 22 | G10: 6 | M10: =F10*Settings!$B$4+G10*Settings!$B$5+H10*Settings!$B$6+I10*Settings!$B$7+J10*Settings!$B$8+K10*Settings!$B$9+L10*Settings!$B$10 | N10: =M10-INDEX(Settings!$G$4:$G$9,MATCH($E10,Settings!$F$4:$F$9,0)) | O10: =N10*INDEX(Settings!$H$4:$H$9,MATCH($E10,Settings!$F$4:$F$9,0)) | P10: HIGH | Q10: BIGGEST ADP ARBITRAGE. But new HC Harbaugh may curb rushing
A11: 45 | B11: QB9 | C11: Brock Purdy | D11: SF | E11: QB | F11: 27 | G11: 3.5 | M11: =F11*Settings!$B$4+G11*Settings!$B$5+H11*Settings!$B$6+I11*Settings!$B$7+J11*Settings!$B$8+K11*Settings!$B$9+L11*Settings!$B$10 | N11: =M11-INDEX(Settings!$G$4:$G$9,MATCH($E11,Settings!$F$4:$F$9,0)) | O11: =N11*INDEX(Settings!$H$4:$H$9,MATCH($E11,Settings!$F$4:$F$9,0)) | P11: HIGH
A12: 62 | B12: QB10 | C12: Lamar Jackson | D12: BAL | E12: QB | F12: 26.5 | G12: 3.5 | M12: =F12*Settings!$B$4+G12*Settings!$B$5+H12*Settings!$B$6+I12*Settings!$B$7+J12*Settings!$B$8+K12*Settings!$B$9+L12*Settings!$B$10 | N12: =M12-INDEX(Settings!$G$4:$G$9,MATCH($E12,Settings!$F$4:$F$9,0)) | O12: =N12*INDEX(Settings!$H$4:$H$9,MATCH($E12,Settings!$F$4:$F$9,0)) | P12: HIGH | Q12: BAL 11.5 win total
A13: 63 | B13: QB11 | C13: Jayden Daniels | D13: WAS | E13: QB | F13: 23.5 | G13: 5 | M13: =F13*Settings!$B$4+G13*Settings!$B$5+H13*Settings!$B$6+I13*Settings!$B$7+J13*Settings!$B$8+K13*Settings!$B$9+L13*Settings!$B$10 | N13: =M13-INDEX(Settings!$G$4:$G$9,MATCH($E13,Settings!$F$4:$F$9,0)) | O13: =N13*INDEX(Settings!$H$4:$H$9,MATCH($E13,Settings!$F$4:$F$9,0)) | P13: HIGH
A14: 64 | B14: QB12 | C14: Bo Nix | D14: DEN | E14: QB | F14: 26.5 | G14: 3.5 | M14: =F14*Settings!$B$4+G14*Settings!$B$5+H14*Settings!$B$6+I14*Settings!$B$7+J14*Settings!$B$8+K14*Settings!$B$9+L14*Settings!$B$10 | N14: =M14-INDEX(Settings!$G$4:$G$9,MATCH($E14,Settings!$F$4:$F$9,0)) | O14: =N14*INDEX(Settings!$H$4:$H$9,MATCH($E14,Settings!$F$4:$F$9,0)) | P14: HIGH
A15: 75 | B15: QB13 | C15: Caleb Williams | D15: CHI | E15: QB | F15: 27 | G15: 3 | M15: =F15*Settings!$B$4+G15*Settings!$B$5+H15*Settings!$B$6+I15*Settings!$B$7+J15*Settings!$B$8+K15*Settings!$B$9+L15*Settings!$B$10 | N15: =M15-INDEX(Settings!$G$4:$G$9,MATCH($E15,Settings!$F$4:$F$9,0)) | O15: =N15*INDEX(Settings!$H$4:$H$9,MATCH($E15,Settings!$F$4:$F$9,0)) | P15: HIGH
A16: 81 | B16: QB14 | C16: Justin Herbert | D16: LAC | E16: QB | F16: 27.5 | G16: 2.5 | M16: =F16*Settings!$B$4+G16*Settings!$B$5+H16*Settings!$B$6+I16*Settings!$B$7+J16*Settings!$B$8+K16*Settings!$B$9+L16*Settings!$B$10 | N16: =M16-INDEX(Settings!$G$4:$G$9,MATCH($E16,Settings!$F$4:$F$9,0)) | O16: =N16*INDEX(Settings!$H$4:$H$9,MATCH($E16,Settings!$F$4:$F$9,0)) | P16: HIGH
A17: 94 | B17: QB15 | C17: Patrick Mahomes | D17: KC | E17: QB | F17: 26 | G17: 3 | M17: =F17*Settings!$B$4+G17*Settings!$B$5+H17*Settings!$B$6+I17*Settings!$B$7+J17*Settings!$B$8+K17*Settings!$B$9+L17*Settings!$B$10 | N17: =M17-INDEX(Settings!$G$4:$G$9,MATCH($E17,Settings!$F$4:$F$9,0)) | O17: =N17*INDEX(Settings!$H$4:$H$9,MATCH($E17,Settings!$F$4:$F$9,0)) | P17: MEDIUM | Q17: INJURY RISK: torn ACL+LCL 2025; no preseason snaps
A18: 146 | B18: QB16 | C18: Jared Goff | D18: DET | E18: QB | F18: 30 | G18: 0.5 | M18: =F18*Settings!$B$4+G18*Settings!$B$5+H18*Settings!$B$6+I18*Settings!$B$7+J18*Settings!$B$8+K18*Settings!$B$9+L18*Settings!$B$10 | N18: =M18-INDEX(Settings!$G$4:$G$9,MATCH($E18,Settings!$F$4:$F$9,0)) | O18: =N18*INDEX(Settings!$H$4:$H$9,MATCH($E18,Settings!$F$4:$F$9,0)) | P18: MEDIUM | Q18: DET 26.1 implied pts; no rush value
A19: 147 | B19: QB17 | C19: Daniel Jones | D19: IND | E19: QB | F19: 21 | G19: 5 | M19: =F19*Settings!$B$4+G19*Settings!$B$5+H19*Settings!$B$6+I19*Settings!$B$7+J19*Settings!$B$8+K19*Settings!$B$9+L19*Settings!$B$10 | N19: =M19-INDEX(Settings!$G$4:$G$9,MATCH($E19,Settings!$F$4:$F$9,0)) | O19: =N19*INDEX(Settings!$H$4:$H$9,MATCH($E19,Settings!$F$4:$F$9,0)) | P19: MEDIUM | Q19: VALUE: Clay 6 rush TD Razzball 7.3; nobody drafts him for that
A20: 153 | B20: QB18 | C20: Tyler Shough | D20: NO | E20: QB | F20: 21.5 | G20: 4.5 | M20: =F20*Settings!$B$4+G20*Settings!$B$5+H20*Settings!$B$6+I20*Settings!$B$7+J20*Settings!$B$8+K20*Settings!$B$9+L20*Settings!$B$10 | N20: =M20-INDEX(Settings!$G$4:$G$9,MATCH($E20,Settings!$F$4:$F$9,0)) | O20: =N20*INDEX(Settings!$H$4:$H$9,MATCH($E20,Settings!$F$4:$F$9,0)) | P20: HIGH
A21: 179 | B21: QB19 | C21: Jordan Love | D21: GB | E21: QB | F21: 26.5 | G21: 1.5 | M21: =F21*Settings!$B$4+G21*Settings!$B$5+H21*Settings!$B$6+I21*Settings!$B$7+J21*Settings!$B$8+K21*Settings!$B$9+L21*Settings!$B$10 | N21: =M21-INDEX(Settings!$G$4:$G$9,MATCH($E21,Settings!$F$4:$F$9,0)) | O21: =N21*INDEX(Settings!$H$4:$H$9,MATCH($E21,Settings!$F$4:$F$9,0)) | P21: HIGH
A22: 197 | B22: QB20 | C22: Baker Mayfield | D22: TB | E22: QB | F22: 25.5 | G22: 1.5 | M22: =F22*Settings!$B$4+G22*Settings!$B$5+H22*Settings!$B$6+I22*Settings!$B$7+J22*Settings!$B$8+K22*Settings!$B$9+L22*Settings!$B$10 | N22: =M22-INDEX(Settings!$G$4:$G$9,MATCH($E22,Settings!$F$4:$F$9,0)) | O22: =N22*INDEX(Settings!$H$4:$H$9,MATCH($E22,Settings!$F$4:$F$9,0)) | P22: MEDIUM
A23: 206 | B23: QB21 | C23: Sam Darnold | D23: SEA | E23: QB | F23: 26 | G23: 1 | M23: =F23*Settings!$B$4+G23*Settings!$B$5+H23*Settings!$B$6+I23*Settings!$B$7+J23*Settings!$B$8+K23*Settings!$B$9+L23*Settings!$B$10 | N23: =M23-INDEX(Settings!$G$4:$G$9,MATCH($E23,Settings!$F$4:$F$9,0)) | O23: =N23*INDEX(Settings!$H$4:$H$9,MATCH($E23,Settings!$F$4:$F$9,0)) | P23: HIGH
A24: 211 | B24: QB22 | C24: Kyler Murray | D24: MIN | E24: QB | F24: 21.5 | G24: 3 | M24: =F24*Settings!$B$4+G24*Settings!$B$5+H24*Settings!$B$6+I24*Settings!$B$7+J24*Settings!$B$8+K24*Settings!$B$9+L24*Settings!$B$10 | N24: =M24-INDEX(Settings!$G$4:$G$9,MATCH($E24,Settings!$F$4:$F$9,0)) | O24: =N24*INDEX(Settings!$H$4:$H$9,MATCH($E24,Settings!$F$4:$F$9,0)) | P24: MEDIUM | Q24: Named Week 1 starter over McCarthy
A25: 225 | B25: QB23 | C25: Bryce Young | D25: CAR | E25: QB | F25: 21.5 | G25: 2.5 | M25: =F25*Settings!$B$4+G25*Settings!$B$5+H25*Settings!$B$6+I25*Settings!$B$7+J25*Settings!$B$8+K25*Settings!$B$9+L25*Settings!$B$10 | N25: =M25-INDEX(Settings!$G$4:$G$9,MATCH($E25,Settings!$F$4:$F$9,0)) | O25: =N25*INDEX(Settings!$H$4:$H$9,MATCH($E25,Settings!$F$4:$F$9,0)) | P25: MEDIUM
A26: 245 | B26: QB24 | C26: C.J. Stroud | D26: HOU | E26: QB | F26: 22.5 | G26: 1.5 | M26: =F26*Settings!$B$4+G26*Settings!$B$5+H26*Settings!$B$6+I26*Settings!$B$7+J26*Settings!$B$8+K26*Settings!$B$9+L26*Settings!$B$10 | N26: =M26-INDEX(Settings!$G$4:$G$9,MATCH($E26,Settings!$F$4:$F$9,0)) | O26: =N26*INDEX(Settings!$H$4:$H$9,MATCH($E26,Settings!$F$4:$F$9,0)) | P26: HIGH | Q26: Vegas is fading him
A27: 253 | B27: QB25 | C27: Aaron Rodgers | D27: PIT | E27: QB | F27: 22 | G27: 1 | M27: =F27*Settings!$B$4+G27*Settings!$B$5+H27*Settings!$B$6+I27*Settings!$B$7+J27*Settings!$B$8+K27*Settings!$B$9+L27*Settings!$B$10 | N27: =M27-INDEX(Settings!$G$4:$G$9,MATCH($E27,Settings!$F$4:$F$9,0)) | O27: =N27*INDEX(Settings!$H$4:$H$9,MATCH($E27,Settings!$F$4:$F$9,0)) | P27: MEDIUM
A28: 265 | B28: QB26 | C28: Geno Smith | D28: NYJ | E28: QB | F28: 19.5 | G28: 1.5 | M28: =F28*Settings!$B$4+G28*Settings!$B$5+H28*Settings!$B$6+I28*Settings!$B$7+J28*Settings!$B$8+K28*Settings!$B$9+L28*Settings!$B$10 | N28: =M28-INDEX(Settings!$G$4:$G$9,MATCH($E28,Settings!$F$4:$F$9,0)) | O28: =N28*INDEX(Settings!$H$4:$H$9,MATCH($E28,Settings!$F$4:$F$9,0)) | P28: MEDIUM | Q28: NYJ lowest implied total 18.4
A29: 267 | B29: QB27 | C29: Malik Willis | D29: MIA | E29: QB | F29: 14 | G29: 4 | M29: =F29*Settings!$B$4+G29*Settings!$B$5+H29*Settings!$B$6+I29*Settings!$B$7+J29*Settings!$B$8+K29*Settings!$B$9+L29*Settings!$B$10 | N29: =M29-INDEX(Settings!$G$4:$G$9,MATCH($E29,Settings!$F$4:$F$9,0)) | O29: =N29*INDEX(Settings!$H$4:$H$9,MATCH($E29,Settings!$F$4:$F$9,0)) | P29: LOW | Q29: LOTTERY TICKET: Yahoo proj 7 rush TD Razzball 2.8
A30: 271 | B30: QB28 | C30: Cam Ward | D30: TEN | E30: QB | F30: 18.5 | G30: 1.5 | M30: =F30*Settings!$B$4+G30*Settings!$B$5+H30*Settings!$B$6+I30*Settings!$B$7+J30*Settings!$B$8+K30*Settings!$B$9+L30*Settings!$B$10 | N30: =M30-INDEX(Settings!$G$4:$G$9,MATCH($E30,Settings!$F$4:$F$9,0)) | O30: =N30*INDEX(Settings!$H$4:$H$9,MATCH($E30,Settings!$F$4:$F$9,0)) | P30: MEDIUM
A31: 280 | B31: QB29 | C31: Jacoby Brissett | D31: ARI | E31: QB | F31: 18 | G31: 1 | M31: =F31*Settings!$B$4+G31*Settings!$B$5+H31*Settings!$B$6+I31*Settings!$B$7+J31*Settings!$B$8+K31*Settings!$B$9+L31*Settings!$B$10 | N31: =M31-INDEX(Settings!$G$4:$G$9,MATCH($E31,Settings!$F$4:$F$9,0)) | O31: =N31*INDEX(Settings!$H$4:$H$9,MATCH($E31,Settings!$F$4:$F$9,0)) | P31: MEDIUM | Q31: ARI 3.5 win total worst in NFL
A32: 281 | B32: QB30 | C32: Fernando Mendoza | D32: LV | E32: QB | F32: 13 | G32: 1.5 | M32: =F32*Settings!$B$4+G32*Settings!$B$5+H32*Settings!$B$6+I32*Settings!$B$7+J32*Settings!$B$8+K32*Settings!$B$9+L32*Settings!$B$10 | N32: =M32-INDEX(Settings!$G$4:$G$9,MATCH($E32,Settings!$F$4:$F$9,0)) | O32: =N32*INDEX(Settings!$H$4:$H$9,MATCH($E32,Settings!$F$4:$F$9,0)) | P32: LOW | Q32: Rookie No.1 overall; Cousins starts Week 1 but handoff expected
A33: 282 | B33: QB31 | C33: Shedeur Sanders | D33: CLE | E33: QB | F33: 11 | G33: 1.5 | M33: =F33*Settings!$B$4+G33*Settings!$B$5+H33*Settings!$B$6+I33*Settings!$B$7+J33*Settings!$B$8+K33*Settings!$B$9+L33*Settings!$B$10 | N33: =M33-INDEX(Settings!$G$4:$G$9,MATCH($E33,Settings!$F$4:$F$9,0)) | O33: =N33*INDEX(Settings!$H$4:$H$9,MATCH($E33,Settings!$F$4:$F$9,0)) | P33: LOW | Q33: Watson named starter but Clay projects Sanders more volume
A34: 283 | B34: QB32 | C34: Tua Tagovailoa | D34: ATL | E34: QB | F34: 12 | M34: =F34*Settings!$B$4+G34*Settings!$B$5+H34*Settings!$B$6+I34*Settings!$B$7+J34*Settings!$B$8+K34*Settings!$B$9+L34*Settings!$B$10 | N34: =M34-INDEX(Settings!$G$4:$G$9,MATCH($E34,Settings!$F$4:$F$9,0)) | O34: =N34*INDEX(Settings!$H$4:$H$9,MATCH($E34,Settings!$F$4:$F$9,0)) | P34: LOW | Q34: ATL QB job unsettled; no rush value either way
A35: 284 | B35: QB33 | C35: Deshaun Watson | D35: CLE | E35: QB | F35: 10 | G35: 1 | M35: =F35*Settings!$B$4+G35*Settings!$B$5+H35*Settings!$B$6+I35*Settings!$B$7+J35*Settings!$B$8+K35*Settings!$B$9+L35*Settings!$B$10 | N35: =M35-INDEX(Settings!$G$4:$G$9,MATCH($E35,Settings!$F$4:$F$9,0)) | O35: =N35*INDEX(Settings!$H$4:$H$9,MATCH($E35,Settings!$F$4:$F$9,0)) | P35: LOW | Q35: Named Week 1 starter; sources conflict badly
A36: 285 | B36: QB34 | C36: Michael Penix Jr. | D36: ATL | E36: QB | F36: 8 | G36: 1 | M36: =F36*Settings!$B$4+G36*Settings!$B$5+H36*Settings!$B$6+I36*Settings!$B$7+J36*Settings!$B$8+K36*Settings!$B$9+L36*Settings!$B$10 | N36: =M36-INDEX(Settings!$G$4:$G$9,MATCH($E36,Settings!$F$4:$F$9,0)) | O36: =N36*INDEX(Settings!$H$4:$H$9,MATCH($E36,Settings!$F$4:$F$9,0)) | P36: LOW | Q36: Recovering from torn ACL not fully cleared
A37: 286 | B37: QB35 | C37: Kirk Cousins | D37: LV | E37: QB | F37: 6 | M37: =F37*Settings!$B$4+G37*Settings!$B$5+H37*Settings!$B$6+I37*Settings!$B$7+J37*Settings!$B$8+K37*Settings!$B$9+L37*Settings!$B$10 | N37: =M37-INDEX(Settings!$G$4:$G$9,MATCH($E37,Settings!$F$4:$F$9,0)) | O37: =N37*INDEX(Settings!$H$4:$H$9,MATCH($E37,Settings!$F$4:$F$9,0)) | P37: LOW
A38: 287 | B38: QB36 | C38: J.J. McCarthy | D38: MIN | E38: QB | F38: 3 | G38: 1 | M38: =F38*Settings!$B$4+G38*Settings!$B$5+H38*Settings!$B$6+I38*Settings!$B$7+J38*Settings!$B$8+K38*Settings!$B$9+L38*Settings!$B$10 | N38: =M38-INDEX(Settings!$G$4:$G$9,MATCH($E38,Settings!$F$4:$F$9,0)) | O38: =N38*INDEX(Settings!$H$4:$H$9,MATCH($E38,Settings!$F$4:$F$9,0)) | P38: LOW | Q38: Lost job to Murray
A39: 288 | B39: QB37 | C39: Justin Fields | D39: KC | E39: QB | F39: 1 | G39: 1 | M39: =F39*Settings!$B$4+G39*Settings!$B$5+H39*Settings!$B$6+I39*Settings!$B$7+J39*Settings!$B$8+K39*Settings!$B$9+L39*Settings!$B$10 | N39: =M39-INDEX(Settings!$G$4:$G$9,MATCH($E39,Settings!$F$4:$F$9,0)) | O39: =N39*INDEX(Settings!$H$4:$H$9,MATCH($E39,Settings!$F$4:$F$9,0)) | P39: LOW | Q39: BEST HANDCUFF IN FORMAT: rushing QB behind Mahomes ACL recovery

Sheet RB
A1: RB — ranked by projected points
A2: Rank | B2: Pos | C2: Player | D2: Tm | E2: P | F2: PassTD | G2: RushTD | H2: RecTD | I2: FG | J2: PAT | K2: DefTD | L2: Saf | M2: Points | N2: VOR | O2: Adj VOR | P2: Conf | Q2: Notes
A3: 2 | B3: RB1 | C3: Jahmyr Gibbs | D3: DET | E3: RB | G3: 13.4 | H3: 3.8 | M3: =F3*Settings!$B$4+G3*Settings!$B$5+H3*Settings!$B$6+I3*Settings!$B$7+J3*Settings!$B$8+K3*Settings!$B$9+L3*Settings!$B$10 | N3: =M3-INDEX(Settings!$G$4:$G$9,MATCH($E3,Settings!$F$4:$F$9,0)) | O3: =N3*INDEX(Settings!$H$4:$H$9,MATCH($E3,Settings!$F$4:$F$9,0)) | P3: HIGH | Q3: Overall RB1
A4: 3 | B4: RB2 | C4: Jonathan Taylor | D4: IND | E4: RB | G4: 12.2 | H4: 1.3 | M4: =F4*Settings!$B$4+G4*Settings!$B$5+H4*Settings!$B$6+I4*Settings!$B$7+J4*Settings!$B$8+K4*Settings!$B$9+L4*Settings!$B$10 | N4: =M4-INDEX(Settings!$G$4:$G$9,MATCH($E4,Settings!$F$4:$F$9,0)) | O4: =N4*INDEX(Settings!$H$4:$H$9,MATCH($E4,Settings!$F$4:$F$9,0)) | P4: HIGH | Q4: True goal-line back
A5: 4 | B5: RB3 | C5: Christian McCaffrey | D5: SF | E5: RB | G5: 9 | H5: 4.4 | M5: =F5*Settings!$B$4+G5*Settings!$B$5+H5*Settings!$B$6+I5*Settings!$B$7+J5*Settings!$B$8+K5*Settings!$B$9+L5*Settings!$B$10 | N5: =M5-INDEX(Settings!$G$4:$G$9,MATCH($E5,Settings!$F$4:$F$9,0)) | O5: =N5*INDEX(Settings!$H$4:$H$9,MATCH($E5,Settings!$F$4:$F$9,0)) | P5: HIGH | Q5: Goal-line yes
A6: 5 | B6: RB4 | C6: Derrick Henry | D6: BAL | E6: RB | G6: 12.8 | H6: 0.6 | M6: =F6*Settings!$B$4+G6*Settings!$B$5+H6*Settings!$B$6+I6*Settings!$B$7+J6*Settings!$B$8+K6*Settings!$B$9+L6*Settings!$B$10 | N6: =M6-INDEX(Settings!$G$4:$G$9,MATCH($E6,Settings!$F$4:$F$9,0)) | O6: =N6*INDEX(Settings!$H$4:$H$9,MATCH($E6,Settings!$F$4:$F$9,0)) | P6: HIGH | Q6: Vegas HIGHER than consensus here
A7: 7 | B7: RB5 | C7: James Cook III | D7: BUF | E7: RB | G7: 10.8 | H7: 1.8 | M7: =F7*Settings!$B$4+G7*Settings!$B$5+H7*Settings!$B$6+I7*Settings!$B$7+J7*Settings!$B$8+K7*Settings!$B$9+L7*Settings!$B$10 | N7: =M7-INDEX(Settings!$G$4:$G$9,MATCH($E7,Settings!$F$4:$F$9,0)) | O7: =N7*INDEX(Settings!$H$4:$H$9,MATCH($E7,Settings!$F$4:$F$9,0)) | P7: HIGH | Q7: Allen vulture tax already priced into line
A8: 8 | B8: RB6 | C8: Josh Jacobs | D8: GB | E8: RB | G8: 11.3 | H8: 1.3 | M8: =F8*Settings!$B$4+G8*Settings!$B$5+H8*Settings!$B$6+I8*Settings!$B$7+J8*Settings!$B$8+K8*Settings!$B$9+L8*Settings!$B$10 | N8: =M8-INDEX(Settings!$G$4:$G$9,MATCH($E8,Settings!$F$4:$F$9,0)) | O8: =N8*INDEX(Settings!$H$4:$H$9,MATCH($E8,Settings!$F$4:$F$9,0)) | P8: HIGH | Q8: Goal-line yes
A9: 10 | B9: RB7 | C9: Bijan Robinson | D9: ATL | E9: RB | G9: 8.7 | H9: 3.3 | M9: =F9*Settings!$B$4+G9*Settings!$B$5+H9*Settings!$B$6+I9*Settings!$B$7+J9*Settings!$B$8+K9*Settings!$B$9+L9*Settings!$B$10 | N9: =M9-INDEX(Settings!$G$4:$G$9,MATCH($E9,Settings!$F$4:$F$9,0)) | O9: =N9*INDEX(Settings!$H$4:$H$9,MATCH($E9,Settings!$F$4:$F$9,0)) | P9: HIGH | Q9: CAUTION only 48 pct of inside-5 carries in 2025
A10: 11 | B10: RB8 | C10: Kyren Williams | D10: LAR | E10: RB | G10: 10.1 | H10: 1.8 | M10: =F10*Settings!$B$4+G10*Settings!$B$5+H10*Settings!$B$6+I10*Settings!$B$7+J10*Settings!$B$8+K10*Settings!$B$9+L10*Settings!$B$10 | N10: =M10-INDEX(Settings!$G$4:$G$9,MATCH($E10,Settings!$F$4:$F$9,0)) | O10: =N10*INDEX(Settings!$H$4:$H$9,MATCH($E10,Settings!$F$4:$F$9,0)) | P10: HIGH | Q10: Alternates drives with Corum
A11: 12 | B11: RB9 | C11: Javonte Williams | D11: DAL | E11: RB | G11: 10.6 | H11: 1.2 | M11: =F11*Settings!$B$4+G11*Settings!$B$5+H11*Settings!$B$6+I11*Settings!$B$7+J11*Settings!$B$8+K11*Settings!$B$9+L11*Settings!$B$10 | N11: =M11-INDEX(Settings!$G$4:$G$9,MATCH($E11,Settings!$F$4:$F$9,0)) | O11: =N11*INDEX(Settings!$H$4:$H$9,MATCH($E11,Settings!$F$4:$F$9,0)) | P11: HIGH | Q11: Goal-line yes
A12: 16 | B12: RB10 | C12: Omarion Hampton | D12: LAC | E12: RB | G12: 9.2 | H12: 1.9 | M12: =F12*Settings!$B$4+G12*Settings!$B$5+H12*Settings!$B$6+I12*Settings!$B$7+J12*Settings!$B$8+K12*Settings!$B$9+L12*Settings!$B$10 | N12: =M12-INDEX(Settings!$G$4:$G$9,MATCH($E12,Settings!$F$4:$F$9,0)) | O12: =N12*INDEX(Settings!$H$4:$H$9,MATCH($E12,Settings!$F$4:$F$9,0)) | P12: HIGH | Q12: Goal-line yes
A13: 18 | B13: RB11 | C13: Chase Brown | D13: CIN | E13: RB | G13: 7.4 | H13: 3.6 | M13: =F13*Settings!$B$4+G13*Settings!$B$5+H13*Settings!$B$6+I13*Settings!$B$7+J13*Settings!$B$8+K13*Settings!$B$9+L13*Settings!$B$10 | N13: =M13-INDEX(Settings!$G$4:$G$9,MATCH($E13,Settings!$F$4:$F$9,0)) | O13: =N13*INDEX(Settings!$H$4:$H$9,MATCH($E13,Settings!$F$4:$F$9,0)) | P13: HIGH | Q13: Vegas LOWER than consensus
A14: 19 | B14: RB12 | C14: Saquon Barkley | D14: PHI | E14: RB | G14: 8.6 | H14: 2.1 | M14: =F14*Settings!$B$4+G14*Settings!$B$5+H14*Settings!$B$6+I14*Settings!$B$7+J14*Settings!$B$8+K14*Settings!$B$9+L14*Settings!$B$10 | N14: =M14-INDEX(Settings!$G$4:$G$9,MATCH($E14,Settings!$F$4:$F$9,0)) | O14: =N14*INDEX(Settings!$H$4:$H$9,MATCH($E14,Settings!$F$4:$F$9,0)) | P14: HIGH | Q14: TRAP: Hurts vultures 8.5 rush TDs; not priced in
... A21: 60 | B21: RB19 | C21: Cam Skattebo | D21: NYG | E21: RB | G21: 7.4 | H21: 1.2 | M21: =F21*Settings!$B$4+G21*Settings!$B$5+H21*Settings!$B$6+I21*Settings!$B$7+J21*Settings!$B$8+K21*Settings!$B$9+L21*Settings!$B$10 | N21: =M21-INDEX(Settings!$G$4:$G$9,MATCH($E21,Settings!$F$4:$F$9,0)) | O21: =N21*INDEX(Settings!$H$4:$H$9,MATCH($E21,Settings!$F$4:$F$9,0)) | P21: HIGH | Q21: Goal-line yes
A22: 61 | B22: RB20 | C22: D'Andre Swift | D22: CHI | E22: RB | G22: 7.5 | H22: 1.1 | M22: =F22*Settings!$B$4+G22*Settings!$B$5+H22*Settings!$B$6+I22*Settings!$B$7+J22*Settings!$B$8+K22*Settings!$B$9+L22*Settings!$B$10 | N22: =M22-INDEX(Settings!$G$4:$G$9,MATCH($E22,Settings!$F$4:$F$9,0)) | O22: =N22*INDEX(Settings!$H$4:$H$9,MATCH($E22,Settings!$F$4:$F$9,0)) | P22: HIGH
A23: 71 | B23: RB21 | C23: Rhamondre Stevenson | D23: NE | E23: RB | G23: 6.9 | H23: 1.6 | M23: =F23*Settings!$B$4+G23*Settings!$B$5+H23*Settings!$B$6+I23*Settings!$B$7+J23*Settings!$B$8+K23*Settings!$B$9+L23*Settings!$B$10 | N23: =M23-INDEX(Settings!$G$4:$G$9,MATCH($E23,Settings!$F$4:$F$9,0)) | O23: =N23*INDEX(Settings!$H$4:$H$9,MATCH($E23,Settings!$F$4:$F$9,0)) | P23: HIGH | Q23: Goal-line yes
A24: 72 | B24: RB22 | C24: Bhayshul Tuten | D24: JAX | E24: RB | G24: 6.8 | H24: 1.7 | M24: =F24*Settings!$B$4+G24*Settings!$B$5+H24*Settings!$B$6+I24*Settings!$B$7+J24*Settings!$B$8+K24*Settings!$B$9+L24*Settings!$B$10 | N24: =M24-INDEX(Settings!$G$4:$G$9,MATCH($E24,Settings!$F$4:$F$9,0)) | O24: =N24*INDEX(Settings!$H$4:$H$9,MATCH($E24,Settings!$F$4:$F$9,0)) | P24: HIGH | Q24: But Rodriguez owns goal line
A25: 79 | B25: RB23 | C25: Bucky Irving | D25: TB | E25: RB | G25: 6.2 | H25: 1.9 | M25: =F25*Settings!$B$4+G25*Settings!$B$5+H25*Settings!$B$6+I25*Settings!$B$7+J25*Settings!$B$8+K25*Settings!$B$9+L25*Settings!$B$10 | N25: =M25-INDEX(Settings!$G$4:$G$9,MATCH($E25,Settings!$F$4:$F$9,0)) | O25: =N25*INDEX(Settings!$H$4:$H$9,MATCH($E25,Settings!$F$4:$F$9,0)) | P25: HIGH | Q25: TRAP: ZERO carries inside the 5 in 2025
A26: 83 | B26: RB24 | C26: Quinshon Judkins | D26: CLE | E26: RB | G26: 7.2 | H26: 0.8 | M26: =F26*Settings!$B$4+G26*Settings!$B$5+H26*Settings!$B$6+I26*Settings!$B$7+J26*Settings!$B$8+K26*Settings!$B$9+L26*Settings!$B$10 | N26: =M26-INDEX(Settings!$G$4:$G$9,MATCH($E26,Settings!$F$4:$F$9,0)) | O26: =N26*INDEX(Settings!$H$4:$H$9,MATCH($E26,Settings!$F$4:$F$9,0)) | P26: HIGH | Q26: Goal-line yes
A27: 84 | B27: RB25 | C27: TreVeyon Henderson | D27: NE | E27: RB | G27: 6.8 | H27: 1.2 | M27: =F27*Settings!$B$4+G27*Settings!$B$5+H27*Settings!$B$6+I27*Settings!$B$7+J27*Settings!$B$8+K27*Settings!$B$9+L27*Settings!$B$10 | N27: =M27-INDEX(Settings!$G$4:$G$9,MATCH($E27,Settings!$F$4:$F$9,0)) | O27: =N27*INDEX(Settings!$H$4:$H$9,MATCH($E27,Settings!$F$4:$F$9,0)) | P27: HIGH | Q27: Not the goal-line back
A28: 92 | B28: RB26 | C28: David Montgomery | D28: HOU | E28: RB | G28: 7 | H28: 0.8 | M28: =F28*Settings!$B$4+G28*Settings!$B$5+H28*Settings!$B$6+I28*Settings!$B$7+J28*Settings!$B$8+K28*Settings!$B$9+L28*Settings!$B$10 | N28: =M28-INDEX(Settings!$G$4:$G$9,MATCH($E28,Settings!$F$4:$F$9,0)) | O28: =N28*INDEX(Settings!$H$4:$H$9,MATCH($E28,Settings!$F$4:$F$9,0)) | P28: HIGH | Q28: Traded DET to HOU
A29: 100 | B29: RB27 | C29: J.K. Dobbins | D29: DEN | E29: RB | G29: 6.8 | H29: 0.9 | M29: =F29*Settings!$B$4+G29*Settings!$B$5+H29*Settings!$B$6+I29*Settings!$B$7+J29*Settings!$B$8+K29*Settings!$B$9+L29*Settings!$B$10 | N29: =M29-INDEX(Settings!$G$4:$G$9,MATCH($E29,Settings!$F$4:$F$9,0)) | O29: =N29*INDEX(Settings!$H$4:$H$9,MATCH($E29,Settings!$F$4:$F$9,0)) | P29: HIGH | Q29: Goal-line yes
A30: 113 | B30: RB28 | C30: Travis Etienne Jr. | D30: NO | E30: RB | G30: 5.6 | H30: 2 | M30: =F30*Settings!$B$4+G30*Settings!$B$5+H30*Settings!$B$6+I30*Settings!$B$7+J30*Settings!$B$8+K30*Settings!$B$9+L30*Settings!$B$10 | N30: =M30-INDEX(Settings!$G$4:$G$9,MATCH($E30,Settings!$F$4:$F$9,0)) | O30: =N30*INDEX(Settings!$H$4:$H$9,MATCH($E30,Settings!$F$4:$F$9,0)) | P30: HIGH | Q30: Traded JAX to NO
A31: 129 | B31: RB29 | C31: Jacory Croskey-Merritt | D31: WAS | E31: RB | G31: 7.2 | H31: 0.3 | M31: =F31*Settings!$B$4+G31*Settings!$B$5+H31*Settings!$B$6+I31*Settings!$B$7+J31*Settings!$B$8+K31*Settings!$B$9+L31*Settings!$B$10 | N31: =M31-INDEX(Settings!$G$4:$G$9,MATCH($E31,Settings!$F$4:$F$9,0)) | O31: =N31*INDEX(Settings!$H$4:$H$9,MATCH($E31,Settings!$F$4:$F$9,0)) | P31: HIGH | Q31: Goal-line yes but rookie Kaytron Allen vultures
A32: 151 | B32: RB30 | C32: Blake Corum | D32: LAR | E32: RB | G32: 6.7 | H32: 0.3 | M32: =F32*Settings!$B$4+G32*Settings!$B$5+H32*Settings!$B$6+I32*Settings!$B$7+J32*Settings!$B$8+K32*Settings!$B$9+L32*Settings!$B$10 | N32: =M32-INDEX(Settings!$G$4:$G$9,MATCH($E32,Settings!$F$4:$F$9,0)) | O32: =N32*INDEX(Settings!$H$4:$H$9,MATCH($E32,Settings!$F$4:$F$9,0)) | P32: HIGH | Q32: Alternates drives with Kyren
A33: 155 | B33: RB31 | C33: Rachaad White | D33: WAS | E33: RB | G33: 5 | H33: 1.9 | M33: =F33*Settings!$B$4+G33*Settings!$B$5+H33*Settings!$B$6+I33*Settings!$B$7+J33*Settings!$B$8+K33*Settings!$B$9+L33*Settings!$B$10 | N33: =M33-INDEX(Settings!$G$4:$G$9,MATCH($E33,Settings!$F$4:$F$9,0)) | O33: =N33*INDEX(Settings!$H$4:$H$9,MATCH($E33,Settings!$F$4:$F$9,0)) | P33: HIGH | Q33: Signed TB to WAS
A34: 166 | B34: RB32 | C34: Jaylen Warren | D34: PIT | E34: RB | G34: 4.8 | H34: 1.8 | M34: =F34*Settings!$B$4+G34*Settings!$B$5+H34*Settings!$B$6+I34*Settings!$B$7+J34*Settings!$B$8+K34*Settings!$B$9+L34*Settings!$B$10 | N34: =M34-INDEX(Settings!$G$4:$G$9,MATCH($E34,Settings!$F$4:$F$9,0)) | O34: =N34*INDEX(Settings!$H$4:$H$9,MATCH($E34,Settings!$F$4:$F$9,0)) | P34: HIGH | Q34: True 50-50 with Dowdle
A35: 188 | B35: RB33 | C35: Rico Dowdle | D35: PIT | E35: RB | G35: 5.2 | H35: 1.1 | M35: =F35*Settings!$B$4+G35*Settings!$B$5+H35*Settings!$B$6+I35*Settings!$B$7+J35*Settings!$B$8+K35*Settings!$B$9+L35*Settings!$B$10 | N35: =M35-INDEX(Settings!$G$4:$G$9,MATCH($E35,Settings!$F$4:$F$9,0)) | O35: =N35*INDEX(Settings!$H$4:$H$9,MATCH($E35,Settings!$F$4:$F$9,0)) | P35: HIGH | Q35: True 50-50 with Warren
A36: 191 | B36: RB34 | C36: Chuba Hubbard | D36: CAR | E36: RB | G36: 4.9 | H36: 1.2 | M36: =F36*Settings!$B$4+G36*Settings!$B$5+H36*Settings!$B$6+I36*Settings!$B$7+J36*Settings!$B$8+K36*Settings!$B$9+L36*Settings!$B$10 | N36: =M36-INDEX(Settings!$G$4:$G$9,MATCH($E36,Settings!$F$4:$F$9,0)) | O36: =N36*INDEX(Settings!$H$4:$H$9,MATCH($E36,Settings!$F$4:$F$9,0)) | P36: MEDIUM
A37: 192 | B37: RB35 | C37: Tony Pollard | D37: TEN | E37: RB | G37: 5.2 | H37: 0.8 | M37: =F37*Settings!$B$4+G37*Settings!$B$5+H37*Settings!$B$6+I37*Settings!$B$7+J37*Settings!$B$8+K37*Settings!$B$9+L37*Settings!$B$10 | N37: =M37-INDEX(Settings!$G$4:$G$9,MATCH($E37,Settings!$F$4:$F$9,0)) | O37: =N37*INDEX(Settings!$H$4:$H$9,MATCH($E37,Settings!$F$4:$F$9,0)) | P37: HIGH
A38: 196 | B38: RB36 | C38: Kyle Monangai | D38: CHI | E38: RB | G38: 5.2 | H38: 0.7 | M38: =F38*Settings!$B$4+G38*Settings!$B$5+H38*Settings!$B$6+I38*Settings!$B$7+J38*Settings!$B$8+K38*Settings!$B$9+L38*Settings!$B$10 | N38: =M38-INDEX(Settings!$G$4:$G$9,MATCH($E38,Settings!$F$4:$F$9,0)) | O38: =N38*INDEX(Settings!$H$4:$H$9,MATCH($E38,Settings!$F$4:$F$9,0)) | P38: MEDIUM
A39: 199 | B39: RB37 | C39: Jordan Mason | D39: MIN | E39: RB | G39: 5.7 | H39: 0.1 | M39: =F39*Settings!$B$4+G39*Settings!$B$5+H39*Settings!$B$6+I39*Settings!$B$7+J39*Settings!$B$8+K39*Settings!$B$9+L39*Settings!$B$10 | N39: =M39-INDEX(Settings!$G$4:$G$9,MATCH($E39,Settings!$F$4:$F$9,0)) | O39: =N39*INDEX(Settings!$H$4:$H$9,MATCH($E39,Settings!$F$4:$F$9,0)) | P39: HIGH | Q39: Goal-line yes; Vegas lower than consensus
A40: 200 | B40: RB38 | C40: RJ Harvey | D40: DEN | E40: RB | G40: 3 | H40: 2.8 | M40: =F40*Settings!$B$4+G40*Settings!$B$5+H40*Settings!$B$6+I40*Settings!$B$7+J40*Settings!$B$8+K40*Settings!$B$9+L40*Settings!$B$10 | N40: =M40-INDEX(Settings!$G$4:$G$9,MATCH($E40,Settings!$F$4:$F$9,0)) | O40: =N40*INDEX(Settings!$H$4:$H$9,MATCH($E40,Settings!$F$4:$F$9,0)) | P40: HIGH
A41: 201 | B41: RB39 | C41: Kenny Gainwell | D41: TB | E41: RB | G41: 3.8 | H41: 2 | M41: =F41*Settings!$B$4+G41*Settings!$B$5+H41*Settings!$B$6+I41*Settings!$B$7+J41*Settings!$B$8+K41*Settings!$B$9+L41*Settings!$B$10 | N41: =M41-INDEX(Settings!$G$4:$G$9,MATCH($E41,Settings!$F$4:$F$9,0)) | O41: =N41*INDEX(Settings!$H$4:$H$9,MATCH($E41,Settings!$F$4:$F$9,0)) | P41: HIGH
A42: 205 | B42: RB40 | C42: Zach Charbonnet | D42: SEA | E42: RB | G42: 5 | H42: 0.7 | M42: =F42*Settings!$B$4+G42*Settings!$B$5+H42*Settings!$B$6+I42*Settings!$B$7+J42*Settings!$B$8+K42*Settings!$B$9+L42*Settings!$B$10 | N42: =M42-INDEX(Settings!$G$4:$G$9,MATCH($E42,Settings!$F$4:$F$9,0)) | O42: =N42*INDEX(Settings!$H$4:$H$9,MATCH($E42,Settings!$F$4:$F$9,0)) | P42: MEDIUM | Q42: Torn ACL Feb surgery; on PUP; ESPN number too aggressive
A43: 214 | B43: RB41 | C43: Jonathon Brooks | D43: CAR | E43: RB | G43: 4.2 | H43: 1.1 | M43: =F43*Settings!$B$4+G43*Settings!$B$5+H43*Settings!$B$6+I43*Settings!$B$7+J43*Settings!$B$8+K43*Settings!$B$9+L43*Settings!$B$10 | N43: =M43-INDEX(Settings!$G$4:$G$9,MATCH($E43,Settings!$F$4:$F$9,0)) | O43: =N43*INDEX(Settings!$H$4:$H$9,MATCH($E43,Settings!$F$4:$F$9,0)) | P43: HIGH | Q43: Repeat ACL history
A44: 228 | B44: RB42 | C44: Aaron Jones Sr. | D44: MIN | E44: RB | G44: 3.1 | H44: 1.6 | M44: =F44*Settings!$B$4+G44*Settings!$B$5+H44*Settings!$B$6+I44*Settings!$B$7+J44*Settings!$B$8+K44*Settings!$B$9+L44*Settings!$B$10 | N44: =M44-INDEX(Settings!$G$4:$G$9,MATCH($E44,Settings!$F$4:$F$9,0)) | O44: =N44*INDEX(Settings!$H$4:$H$9,MATCH($E44,Settings!$F$4:$F$9,0)) | P44: HIGH
A45: 248 | B45: RB43 | C45: Isiah Pacheco | D45: DET | E45: RB | G45: 3.8 | H45: 0.4 | M45: =F45*Settings!$B$4+G45*Settings!$B$5+H45*Settings!$B$6+I45*Settings!$B$7+J45*Settings!$B$8+K45*Settings!$B$9+L45*Settings!$B$10 | N45: =M45-INDEX(Settings!$G$4:$G$9,MATCH($E45,Settings!$F$4:$F$9,0)) | O45: =N45*INDEX(Settings!$H$4:$H$9,MATCH($E45,Settings!$F$4:$F$9,0)) | P45: HIGH | Q45: Signed KC to DET
A46: 249 | B46: RB44 | C46: Brian Robinson Jr. | D46: ATL | E46: RB | G46: 3.9 | H46: 0.1 | M46: =F46*Settings!$B$4+G46*Settings!$B$5+H46*Settings!$B$6+I46*Settings!$B$7+J46*Settings!$B$8+K46*Settings!$B$9+L46*Settings!$B$10 | N46: =M46-INDEX(Settings!$G$4:$G$9,MATCH($E46,Settings!$F$4:$F$9,0)) | O46: =N46*INDEX(Settings!$H$4:$H$9,MATCH($E46,Settings!$F$4:$F$9,0)) | P46: HIGH | Q46: Vultures Bijan at goal line
...

Sheet WR
A1: WR — ranked by projected points
A2: Rank | B2: Pos | C2: Player | D2: Tm | E2: P | F2: PassTD | G2: RushTD | H2: RecTD | I2: FG | J2: PAT | K2: DefTD | L2: Saf | M2: Points | N2: VOR | O2: Adj VOR | P2: Conf | Q2: Notes
A3: 9 | B3: WR1 | C3: Ja'Marr Chase | D3: CIN | E3: WR | G3: 0.1 | H3: 10.9 | M3: =F3*Settings!$B$4+G3*Settings!$B$5+H3*Settings!$B$6+I3*Settings!$B$7+J3*Settings!$B$8+K3*Settings!$B$9+L3*Settings!$B$10 | N3: =M3-INDEX(Settings!$G$4:$G$9,MATCH($E3,Settings!$F$4:$F$9,0)) | O3: =N3*INDEX(Settings!$H$4:$H$9,MATCH($E3,Settings!$F$4:$F$9,0)) | P3: HIGH
A4: 13 | B4: WR2 | C4: Davante Adams | D4: LAR | E4: WR | H4: 10.3 | M4: =F4*Settings!$B$4+G4*Settings!$B$5+H4*Settings!$B$6+I4*Settings!$B$7+J4*Settings!$B$8+K4*Settings!$B$9+L4*Settings!$B$10 | N4: =M4-INDEX(Settings!$G$4:$G$9,MATCH($E4,Settings!$F$4:$F$9,0)) | O4: =N4*INDEX(Settings!$H$4:$H$9,MATCH($E4,Settings!$F$4:$F$9,0)) | P4: HIGH
A5: 14 | B5: WR3 | C5: Amon-Ra St. Brown | D5: DET | E5: WR | G5: 0.1 | H5: 10.2 | M5: =F5*Settings!$B$4+G5*Settings!$B$5+H5*Settings!$B$6+I5*Settings!$B$7+J5*Settings!$B$8+K5*Settings!$B$9+L5*Settings!$B$10 | N5: =M5-INDEX(Settings!$G$4:$G$9,MATCH($E5,Settings!$F$4:$F$9,0)) | O5: =N5*INDEX(Settings!$H$4:$H$9,MATCH($E5,Settings!$F$4:$F$9,0)) | P5: HIGH
A6: 15 | B6: WR4 | C6: Puka Nacua | D6: LAR | E6: WR | G6: 0.6 | H6: 9.3 | M6: =F6*Settings!$B$4+G6*Settings!$B$5+H6*Settings!$B$6+I6*Settings!$B$7+J6*Settings!$B$8+K6*Settings!$B$9+L6*Settings!$B$10 | N6: =M6-INDEX(Settings!$G$4:$G$9,MATCH($E6,Settings!$F$4:$F$9,0)) | O6: =N6*INDEX(Settings!$H$4:$H$9,MATCH($E6,Settings!$F$4:$F$9,0)) | P6: HIGH
A7: 26 | B7: WR5 | C7: CeeDee Lamb | D7: DAL | E7: WR | G7: 0.1 | H7: 8.3 | M7: =F7*Settings!$B$4+G7*Settings!$B$5+H7*Settings!$B$6+I7*Settings!$B$7+J7*Settings!$B$8+K7*Settings!$B$9+L7*Settings!$B$10 | N7: =M7-INDEX(Settings!$G$4:$G$9,MATCH($E7,Settings!$F$4:$F$9,0)) | O7: =N7*INDEX(Settings!$H$4:$H$9,MATCH($E7,Settings!$F$4:$F$9,0)) | P7: HIGH
A8: 28 | B8: WR6 | C8: Jaxon Smith-Njigba | D8: SEA | E8: WR | G8: 0.1 | H8: 8.2 | M8: =F8*Settings!$B$4+G8*Settings!$B$5+H8*Settings!$B$6+I8*Settings!$B$7+J8*Settings!$B$8+K8*Settings!$B$9+L8*Settings!$B$10 | N8: =M8-INDEX(Settings!$G$4:$G$9,MATCH($E8,Settings!$F$4:$F$9,0)) | O8: =N8*INDEX(Settings!$H$4:$H$9,MATCH($E8,Settings!$F$4:$F$9,0)) | P8: HIGH
A9: 30 | B9: WR7 | C9: Rashee Rice | D9: KC | E9: WR | G9: 0.3 | H9: 7.9 | M9: =F9*Settings!$B$4+G9*Settings!$B$5+H9*Settings!$B$6+I9*Settings!$B$7+J9*Settings!$B$8+K9*Settings!$B$9+L9*Settings!$B$10 | N9: =M9-INDEX(Settings!$G$4:$G$9,MATCH($E9,Settings!$F$4:$F$9,0)) | O9: =N9*INDEX(Settings!$H$4:$H$9,MATCH($E9,Settings!$F$4:$F$9,0)) | P9: HIGH
A10: 31 | B10: WR8 | C10: Tee Higgins | D10: CIN | E10: WR | H10: 8.2 | M10: =F10*Settings!$B$4+G10*Settings!$B$5+H10*Settings!$B$6+I10*Settings!$B$7+J10*Settings!$B$8+K10*Settings!$B$9+L10*Settings!$B$10 | N10: =M10-INDEX(Settings!$G$4:$G$9,MATCH($E10,Settings!$F$4:$F$9,0)) | O10: =N10*INDEX(Settings!$H$4:$H$9,MATCH($E10,Settings!$F$4:$F$9,0)) | P10: HIGH
A11: 36 | B11: WR9 | C11: Rome Odunze | D11: CHI | E11: WR | H11: 7.7 | M11: =F11*Settings!$B$4+G11*Settings!$B$5+H11*Settings!$B$6+I11*Settings!$B$7+J11*Settings!$B$8+K11*Settings!$B$9+L11*Settings!$B$10 | N11: =M11-INDEX(Settings!$G$4:$G$9,MATCH($E11,Settings!$F$4:$F$9,0)) | O11: =N11*INDEX(Settings!$H$4:$H$9,MATCH($E11,Settings!$F$4:$F$9,0)) | P11: HIGH
A12: 39 | B12: WR10 | C12: George Pickens | D12: DAL | E12: WR | H12: 7.6 | M12: =F12*Settings!$B$4+G12*Settings!$B$5+H12*Settings!$B$6+I12*Settings!$B$7+J12*Settings!$B$8+K12*Settings!$B$9+L12*Settings!$B$10 | N12: =M12-INDEX(Settings!$G$4:$G$9,MATCH($E12,Settings!$F$4:$F$9,0)) | O12: =N12*INDEX(Settings!$H$4:$H$9,MATCH($E12,Settings!$F$4:$F$9,0)) | P12: HIGH
A13: 47 | B13: WR11 | C13: Malik Nabers | D13: NYG | E13: WR | G13: 0.1 | H13: 7.2 | M13: =F13*Settings!$B$4+G13*Settings!$B$5+H13*Settings!$B$6+I13*Settings!$B$7+J13*Settings!$B$8+K13*Settings!$B$9+L13*Settings!$B$10 | N13: =M13-INDEX(Settings!$G$4:$G$9,MATCH($E13,Settings!$F$4:$F$9,0)) | O13: =N13*INDEX(Settings!$H$4:$H$9,MATCH($E13,Settings!$F$4:$F$9,0)) | P13: HIGH
A14: 48 | B14: WR12 | C14: Emeka Egbuka | D14: TB | E14: WR | G14: 0.1 | H14: 7.2 | M14: =F14*Settings!$B$4+G14*Settings!$B$5+H14*Settings!$B$6+I14*Settings!$B$7+J14*Settings!$B$8+K14*Settings!$B$9+L14*Settings!$B$10 | N14: =M14-INDEX(Settings!$G$4:$G$9,MATCH($E14,Settings!$F$4:$F$9,0)) | O14: =N14*INDEX(Settings!$H$4:$H$9,MATCH($E14,Settings!$F$4:$F$9,0)) | P14: HIGH
A15: 49 | B15: WR13 | C15: Courtland Sutton | D15: DEN | E15: WR | H15: 7.3 | M15: =F15*Settings!$B$4+G15*Settings!$B$5+H15*Settings!$B$6+I15*Settings!$B$7+J15*Settings!$B$8+K15*Settings!$B$9+L15*Settings!$B$10 | N15: =M15-INDEX(Settings!$G$4:$G$9,MATCH($E15,Settings!$F$4:$F$9,0)) | O15: =N15*INDEX(Settings!$H$4:$H$9,MATCH($E15,Settings!$F$4:$F$9,0)) | P15: HIGH
A16: 50 | B16: WR14 | C16: Justin Jefferson | D16: MIN | E16: WR | G16: 0.1 | H16: 7.2 | M16: =F16*Settings!$B$4+G16*Settings!$B$5+H16*Settings!$B$6+I16*Settings!$B$7+J16*Settings!$B$8+K16*Settings!$B$9+L16*Settings!$B$10 | N16: =M16-INDEX(Settings!$G$4:$G$9,MATCH($E16,Settings!$F$4:$F$9,0)) | O16: =N16*INDEX(Settings!$H$4:$H$9,MATCH($E16,Settings!$F$4:$F$9,0)) | P16: HIGH
A17: 55 | B17: WR15 | C17: Drake London | D17: ATL | E17: WR | H17: 7.2 | M17: =F17*Settings!$B$4+G17*Settings!$B$5+H17*Settings!$B$6+I17*Settings!$B$7+J17*Settings!$B$8+K17*Settings!$B$9+L17*Settings!$B$10 | N17: =M17-INDEX(Settings!$G$4:$G$9,MATCH($E17,Settings!$F$4:$F$9,0)) | O17: =N17*INDEX(Settings!$H$4:$H$9,MATCH($E17,Settings!$F$4:$F$9,0)) | P17: HIGH
A18: 57 | B18: WR16 | C18: Christian Watson | D18: GB | E18: WR | G18: 0.1 | H18: 7 | M18: =F18*Settings!$B$4+G18*Settings!$B$5+H18*Settings!$B$6+I18*Settings!$B$7+J18*Settings!$B$8+K18*Settings!$B$9+L18*Settings!$B$10 | N18: =M18-INDEX(Settings!$G$4:$G$9,MATCH($E18,Settings!$F$4:$F$9,0)) | O18: =N18*INDEX(Settings!$H$4:$H$9,MATCH($E18,Settings!$F$4:$F$9,0)) | P18: HIGH
A19: 68 | B19: WR17 | C19: A.J. Brown | D19: NE | E19: WR | H19: 7 | M19: =F19*Settings!$B$4+G19*Settings!$B$5+H19*Settings!$B$6+I19*Settings!$B$7+J19*Settings!$B$8+K19*Settings!$B$9+L19*Settings!$B$10 | N19: =M19-INDEX(Settings!$G$4:$G$9,MATCH($E19,Settings!$F$4:$F$9,0)) | O19: =N19*INDEX(Settings!$H$4:$H$9,MATCH($E19,Settings!$F$4:$F$9,0)) | P19: HIGH
A20: 73 | B20: WR18 | C20: Nico Collins | D20: HOU | E20: WR | G20: 0.1 | H20: 6.8 | M20: =F20*Settings!$B$4+G20*Settings!$B$5+H20*Settings!$B$6+I20*Settings!$B$7+J20*Settings!$B$8+K20*Settings!$B$9+L20*Settings!$B$10 | N20: =M20-INDEX(Settings!$G$4:$G$9,MATCH($E20,Settings!$F$4:$F$9,0)) | O20: =N20*INDEX(Settings!$H$4:$H$9,MATCH($E20,Settings!$F$4:$F$9,0)) | P20: HIGH
A21: 74 | B21: WR19 | C21: Chris Olave | D21: NO | E21: WR | H21: 6.8 | M21: =F21*Settings!$B$4+G21*Settings!$B$5+H21*Settings!$B$6+I21*Settings!$B$7+J21*Settings!$B$8+K21*Settings!$B$9+L21*Settings!$B$10 | N21: =M21-INDEX(Settings!$G$4:$G$9,MATCH($E21,Settings!$F$4:$F$9,0)) | O21: =N21*INDEX(Settings!$H$4:$H$9,MATCH($E21,Settings!$F$4:$F$9,0)) | P21: HIGH
A22: 76 | B22: WR20 | C22: D.J. Moore | D22: BUF | E22: WR | G22: 0.2 | H22: 6.5 | M22: =F22*Settings!$B$4+G22*Settings!$B$5+H22*Settings!$B$6+I22*Settings!$B$7+J22*Settings!$B$8+K22*Settings!$B$9+L22*Settings!$B$10 | N22: =M22-INDEX(Settings!$G$4:$G$9,MATCH($E22,Settings!$F$4:$F$9,0)) | O22: =N22*INDEX(Settings!$H$4:$H$9,MATCH($E22,Settings!$F$4:$F$9,0)) | P22: HIGH
A23: 78 | B23: WR21 | C23: Jameson Williams | D23: DET | E23: WR | G23: 0.3 | H23: 6.3 | M23: =F23*Settings!$B$4+G23*Settings!$B$5+H23*Settings!$B$6+I23*Settings!$B$7+J23*Settings!$B$8+K23*Settings!$B$9+L23*Settings!$B$10 | N23: =M23-INDEX(Settings!$G$4:$G$9,MATCH($E23,Settings!$F$4:$F$9,0)) | O23: =N23*INDEX(Settings!$H$4:$H$9,MATCH($E23,Settings!$F$4:$F$9,0)) | P23: HIGH
A24: 86 | B24: WR22 | C24: Mike Evans | D24: SF | E24: WR | H24: 6.4 | M24: =F24*Settings!$B$4+G24*Settings!$B$5+H24*Settings!$B$6+I24*Settings!$B$7+J24*Settings!$B$8+K24*Settings!$B$9+L24*Settings!$B$10 | N24: =M24-INDEX(Settings!$G$4:$G$9,MATCH($E24,Settings!$F$4:$F$9,0)) | O24: =N24*INDEX(Settings!$H$4:$H$9,MATCH($E24,Settings!$F$4:$F$9,0)) | P24: HIGH
A25: 93 | B25: WR23 | C25: Ladd McConkey | D25: LAC | E25: WR | H25: 6.2 | M25: =F25*Settings!$B$4+G25*Settings!$B$5+H25*Settings!$B$6+I25*Settings!$B$7+J25*Settings!$B$8+K25*Settings!$B$9+L25*Settings!$B$10 | N25: =M25-INDEX(Settings!$G$4:$G$9,MATCH($E25,Settings!$F$4:$F$9,0)) | O25: =N25*INDEX(Settings!$H$4:$H$9,MATCH($E25,Settings!$F$4:$F$9,0)) | P25: HIGH
A26: 102 | B26: WR24 | C26: DK Metcalf | D26: PIT | E26: WR | H26: 6.1 | M26: =F26*Settings!$B$4+G26*Settings!$B$5+H26*Settings!$B$6+I26*Settings!$B$7+J26*Settings!$B$8+K26*Settings!$B$9+L26*Settings!$B$10 | N26: =M26-INDEX(Settings!$G$4:$G$9,MATCH($E26,Settings!$F$4:$F$9,0)) | O26: =N26*INDEX(Settings!$H$4:$H$9,MATCH($E26,Settings!$F$4:$F$9,0)) | P26: HIGH
A27: 103 | B27: WR25 | C27: Jaylen Waddle | D27: DEN | E27: WR | G27: 0.1 | H27: 6 | M27: =F27*Settings!$B$4+G27*Settings!$B$5+H27*Settings!$B$6+I27*Settings!$B$7+J27*Settings!$B$8+K27*Settings!$B$9+L27*Settings!$B$10 | N27: =M27-INDEX(Settings!$G$4:$G$9,MATCH($E27,Settings!$F$4:$F$9,0)) | O27: =N27*INDEX(Settings!$H$4:$H$9,MATCH($E27,Settings!$F$4:$F$9,0)) | P27: HIGH
A28: 114 | B28: WR26 | C28: DeVonta Smith | D28: PHI | E28: WR | H28: 6 | M28: =F28*Settings!$B$4+G28*Settings!$B$5+H28*Settings!$B$6+I28*Settings!$B$7+J28*Settings!$B$8+K28*Settings!$B$9+L28*Settings!$B$10 | N28: =M28-INDEX(Settings!$G$4:$G$9,MATCH($E28,Settings!$F$4:$F$9,0)) | O28: =N28*INDEX(Settings!$H$4:$H$9,MATCH($E28,Settings!$F$4:$F$9,0)) | P28: HIGH
A29: 115 | B29: WR27 | C29: Tetairoa McMillan | D29: CAR | E29: WR | H29: 6 | M29: =F29*Settings!$B$4+G29*Settings!$B$5+H29*Settings!$B$6+I29*Settings!$B$7+J29*Settings!$B$8+K29*Settings!$B$9+L29*Settings!$B$10 | N29: =M29-INDEX(Settings!$G$4:$G$9,MATCH($E29,Settings!$F$4:$F$9,0)) | O29: =N29*INDEX(Settings!$H$4:$H$9,MATCH($E29,Settings!$F$4:$F$9,0)) | P29: HIGH
A30: 116 | B30: WR28 | C30: Terry McLaurin | D30: WAS | E30: WR | H30: 6 | M30: =F30*Settings!$B$4+G30*Settings!$B$5+H30*Settings!$B$6+I30*Settings!$B$7+J30*Settings!$B$8+K30*Settings!$B$9+L30*Settings!$B$10 | N30: =M30-INDEX(Settings!$G$4:$G$9,MATCH($E30,Settings!$F$4:$F$9,0)) | O30: =N30*INDEX(Settings!$H$4:$H$9,MATCH($E30,Settings!$F$4:$F$9,0)) | P30: HIGH
A31: 117 | B31: WR29 | C31: Zay Flowers | D31: BAL | E31: WR | G31: 0.2 | H31: 5.8 | M31: =F31*Settings!$B$4+G31*Settings!$B$5+H31*Settings!$B$6+I31*Settings!$B$7+J31*Settings!$B$8+K31*Settings!$B$9+L31*Settings!$B$10 | N31: =M31-INDEX(Settings!$G$4:$G$9,MATCH($E31,Settings!$F$4:$F$9,0)) | O31: =N31*INDEX(Settings!$H$4:$H$9,MATCH($E31,Settings!$F$4:$F$9,0)) | P31: HIGH
A32: 128 | B32: WR30 | C32: Quentin Johnston | D32: LAC | E32: WR | G32: 0.1 | H32: 5.8 | M32: =F32*Settings!$B$4+G32*Settings!$B$5+H32*Settings!$B$6+I32*Settings!$B$7+J32*Settings!$B$8+K32*Settings!$B$9+L32*Settings!$B$10 | N32: =M32-INDEX(Settings!$G$4:$G$9,MATCH($E32,Settings!$F$4:$F$9,0)) | O32: =N32*INDEX(Settings!$H$4:$H$9,MATCH($E32,Settings!$F$4:$F$9,0)) | P32: HIGH
A33: 145 | B33: WR31 | C33: Luther Burden III | D33: CHI | E33: WR | G33: 0.2 | H33: 5.5 | M33: =F33*Settings!$B$4+G33*Settings!$B$5+H33*Settings!$B$6+I33*Settings!$B$7+J33*Settings!$B$8+K33*Settings!$B$9+L33*Settings!$B$10 | N33: =M33-INDEX(Settings!$G$4:$G$9,MATCH($E33,Settings!$F$4:$F$9,0)) | O33: =N33*INDEX(Settings!$H$4:$H$9,MATCH($E33,Settings!$F$4:$F$9,0)) | P33: HIGH
A34: 149 | B34: WR32 | C34: Marvin Harrison Jr. | D34: ARI | E34: WR | H34: 5.5 | M34: =F34*Settings!$B$4+G34*Settings!$B$5+H34*Settings!$B$6+I34*Settings!$B$7+J34*Settings!$B$8+K34*Settings!$B$9+L34*Settings!$B$10 | N34: =M34-INDEX(Settings!$G$4:$G$9,MATCH($E34,Settings!$F$4:$F$9,0)) | O34: =N34*INDEX(Settings!$H$4:$H$9,MATCH($E34,Settings!$F$4:$F$9,0)) | P34: HIGH
A35: 156 | B35: WR33 | C35: Romeo Doubs | D35: NE | E35: WR | H35: 5.2 | M35: =F35*Settings!$B$4+G35*Settings!$B$5+H35*Settings!$B$6+I35*Settings!$B$7+J35*Settings!$B$8+K35*Settings!$B$9+L35*Settings!$B$10 | N35: =M35-INDEX(Settings!$G$4:$G$9,MATCH($E35,Settings!$F$4:$F$9,0)) | O35: =N35*INDEX(Settings!$H$4:$H$9,MATCH($E35,Settings!$F$4:$F$9,0)) | P35: HIGH
A36: 157 | B36: WR34 | C36: Alec Pierce | D36: IND | E36: WR | H36: 5.2 | M36: =F36*Settings!$B$4+G36*Settings!$B$5+H36*Settings!$B$6+I36*Settings!$B$7+J36*Settings!$B$8+K36*Settings!$B$9+L36*Settings!$B$10 | N36: =M36-INDEX(Settings!$G$4:$G$9,MATCH($E36,Settings!$F$4:$F$9,0)) | O36: =N36*INDEX(Settings!$H$4:$H$9,MATCH($E36,Settings!$F$4:$F$9,0)) | P36: HIGH
A37: 158 | B37: WR35 | C37: Jakobi Meyers | D37: JAX | E37: WR | G37: 0.1 | H37: 5.1 | M37: =F37*Settings!$B$4+G37*Settings!$B$5+H37*Settings!$B$6+I37*Settings!$B$7+J37*Settings!$B$8+K37*Settings!$B$9+L37*Settings!$B$10 | N37: =M37-INDEX(Settings!$G$4:$G$9,MATCH($E37,Settings!$F$4:$F$9,0)) | O37: =N37*INDEX(Settings!$H$4:$H$9,MATCH($E37,Settings!$F$4:$F$9,0)) | P37: HIGH
A38: 159 | B38: WR36 | C38: Jordan Addison | D38: MIN | E38: WR | G38: 0.1 | H38: 5.1 | M38: =F38*Settings!$B$4+G38*Settings!$B$5+H38*Settings!$B$6+I38*Settings!$B$7+J38*Settings!$B$8+K38*Settings!$B$9+L38*Settings!$B$10 | N38: =M38-INDEX(Settings!$G$4:$G$9,MATCH($E38,Settings!$F$4:$F$9,0)) | O38: =N38*INDEX(Settings!$H$4:$H$9,MATCH($E38,Settings!$F$4:$F$9,0)) | P38: HIGH
A39: 160 | B39: WR37 | C39: Garrett Wilson | D39: NYJ | E39: WR | G39: 0.1 | H39: 5.1 | M39: =F39*Settings!$B$4+G39*Settings!$B$5+H39*Settings!$B$6+I39*Settings!$B$7+J39*Settings!$B$8+K39*Settings!$B$9+L39*Settings!$B$10 | N39: =M39-INDEX(Settings!$G$4:$G$9,MATCH($E39,Settings!$F$4:$F$9,0)) | O39: =N39*INDEX(Settings!$H$4:$H$9,MATCH($E39,Settings!$F$4:$F$9,0)) | P39: HIGH
A40: 161 | B40: WR38 | C40: Parker Washington | D40: JAX | E40: WR | G40: 0.1 | H40: 5.1 | M40: =F40*Settings!$B$4+G40*Settings!$B$5+H40*Settings!$B$6+I40*Settings!$B$7+J40*Settings!$B$8+K40*Settings!$B$9+L40*Settings!$B$10 | N40: =M40-INDEX(Settings!$G$4:$G$9,MATCH($E40,Settings!$F$4:$F$9,0)) | O40: =N40*INDEX(Settings!$H$4:$H$9,MATCH($E40,Settings!$F$4:$F$9,0)) | P40: HIGH
...

Sheet TE
A1: TE — ranked by projected points
A2: Rank | B2: Pos | C2: Player | D2: Tm | E2: P | F2: PassTD | G2: RushTD | H2: RecTD | I2: FG | J2: PAT | K2: DefTD | L2: Saf | M2: Points | N2: VOR | O2: Adj VOR | P2: Conf | Q2: Notes
A3: 21 | B3: TE1 | C3: Brock Bowers | D3: LV | E3: TE | G3: 0.1 | H3: 6.8 | M3: =F3*Settings!$B$4+G3*Settings!$B$5+H3*Settings!$B$6+I3*Settings!$B$7+J3*Settings!$B$8+K3*Settings!$B$9+L3*Settings!$B$10 | N3: =M3-INDEX(Settings!$G$4:$G$9,MATCH($E3,Settings!$F$4:$F$9,0)) | O3: =N3*INDEX(Settings!$H$4:$H$9,MATCH($E3,Settings!$F$4:$F$9,0)) | P3: HIGH
